Workbook

Sheet Sheet1
A1: ID | B1: Hora de inicio | C1: Hora de finalización | D1: Correo electrónico | E1: Nombre | F1: Hora de la última modificación | G1: Nombre completo | H1: Rut (formato 12345678-9) | I1: LUNES 23 DE FEBRERO OP1: TOMATICAN CON ARROZOP2: POLLO AL JUGO CON ARROZOP3: HIPO TUTO CON REPOLLO-ZAPALLO ITALIANO-ZANAHORIA | J1: MARTES 24 DE FEBRERO OP1: POROTOS PILCO CON CHORIZO OP2: PRIETAS LIONESA CON PUREOP3: HIPO HAMBURGUESA DE VACUNO CON LECHUGA-TOMATE-CHOCLO | K1: MIERCOLES 25 DE FEBRERO OP1: CARNE MONGOLIANA CON ARROZOP2: CHAMPIÑON SALTEADO CON ARROZOP3: HIPO FRITO DE ATUN CON LECHUGA-PAPAS COCIDAS-CEBOLLA EN PLUMAS | L1: JUEVES 26 DE FEBRERO OP1: POLLO CUBOS ARVERJADO CON QUIFAROS OP2: POLLO PESTO CON QUIFAROS OP3: HIPO BISTEC DE POLLO CON POROTO VERDE -TOMATE-HABAS | M1: VIERNES 27 DE FEBRERO OP1: CHULETA ASADA CON ARROZ Y PAPAS FRITAS OP2: MILANESA DE POLLO CON ARROZ Y PAPAS FRITAS
A2: 1 | B2: 46069.58 | C2: 46069.581 | D2: anonymous | G2: XIMENA SALAZAR | H2: 8456853-8 | I2: VACACIONES/ADMINISTRATIVO | J2: Opción 3 | K2: VACACIONES/ADMINISTRATIVO | L2: VACACIONES/ADMINISTRATIVO | M2: VACACIONES/ADMINISTRATIVO
A3: 2 | B3: 46069.637 | C3: 46069.638 | D3: anonymous | G3: Diego Muñoz | H3: 21081008-0 | I3: Opción 3 | J3: Opción 3 | K3: Opción 1 | L3: Opción 3 | M3: Opción 2
A4: 3 | B4: 46069.637 | C4: 46069.638 | D4: anonymous | G4: Williams Tomas Escalona Maldonado | H4: 19818673-2 | I4: Opción 1 | J4: Opción 1 | K4: Opción 2 | L4: Opción 3 | M4: Opción 1
A5: 4 | B5: 46069.637 | C5: 46069.638 | D5: anonymous | G5: Kevin Ávila arce | H5: 18925037-1 | I5: Opción 3 | J5: Opción 3 | K5: Opción 1 | L5: Opción 3 | M5: Opción 2
A6: 5 | B6: 46069.638 | C6: 46069.639 | D6: anonymous | G6: Diana | H6: 25781650-8 | I6: VACACIONES/ADMINISTRATIVO | J6: VACACIONES/ADMINISTRATIVO | K6: VACACIONES/ADMINISTRATIVO | L6: Opción 2 | M6: Opción 2
A7: 6 | B7: 46069.637 | C7: 46069.639 | D7: anonymous | G7: Ariel Camus Vera | H7: 17415201-2 | I7: Opción 2 | J7: Opción 1 | K7: Opción 1 | L7: Opción 1 | M7: Opción 1
A8: 7 | B8: 46069.637 | C8: 46069.639 | D8: anonymous | G8: Miguel angel Negron bustos | H8: 19280241-5 | I8: Opción 2 | J8: Opción 3 | K8: Opción 3 | L8: Opción 3 | M8: Opción 2
A9: 8 | B9: 46069.637 | C9: 46069.639 | D9: anonymous | G9: Miguel duran irarrazabal | H9: 18127633-9 | I9: Opción 1 | J9: Opción 3 | K9: Opción 3 | L9: Opción 3 | M9: Opción 2
A10: 9 | B10: 46069.638 | C10: 46069.639 | D10: anonymous | G10: Axel acuña peña | H10: 20910090-8 | I10: Opción 3 | J10: Opción 3 | K10: Opción 3 | L10: Opción 3 | M10: Opción 2
A11: 10 | B11: 46069.638 | C11: 46069.639 | D11: anonymous | G11: BASTIÁN PÉREZ OJEDA | H11: 197429658 | I11: Opción 3 | J11: Opción 3 | K11: Opción 1 | L11: Opción 3 | M11: Opción 1
A12: 11 | B12: 46069.638 | C12: 46069.639 | D12: anonymous | G12: Pablo Damian Maureira Mendoza | H12: 19001512-2 | I12: Opción 1 | J12: Opción 3 | K12: Opción 1 | L12: Opción 2 | M12: Opción 2
A13: 12 | B13: 46069.638 | C13: 46069.639 | D13: anonymous | G13: Benjamín Andrés Molina Zúñiga | H13: 20048416-9 | I13: Opción 3 | J13: Opción 3 | K13: Opción 1 | L13: Opción 3 | M13: Opción 2
... A115: 114 | B115: 46072.513 | C115: 46072.515 | D115: anonymous | G115: Luis Morales | H115: 98926526 | I115: Opción 2 | J115: Opción 1 | K115: Opción 2 | L115: Opción 2 | M115: Opción 2

Sheet Hoja2
A1: ID | B1: RUT | C1: Nombre completo | D1: LUNES 23 DE FEBRERO OP1: TOMATICAN CON ARROZOP2: POLLO AL JUGO CON ARROZOP3: HIPO TUTO CON REPOLLO-ZAPALLO ITALIANO-ZANAHORIA | E1: MARTES 24 DE FEBRERO OP1: POROTOS PILCO CON CHORIZO OP2: PRIETAS LIONESA CON PUREOP3: HIPO HAMBURGUESA DE VACUNO CON LECHUGA-TOMATE-CHOCLO | F1: MIERCOLES 25 DE FEBRERO OP1: CARNE MONGOLIANA CON ARROZOP2: CHAMPIÑON SALTEADO CON ARROZOP3: HIPO FRITO DE ATUN CON LECHUGA-PAPAS COCIDAS-CEBOLLA EN PLUMAS | G1: JUEVES 26 DE FEBRERO OP1: POLLO CUBOS ARVERJADO CON QUIFAROS OP2: POLLO PESTO CON QUIFAROS OP3: HIPO BISTEC DE POLLO CON POROTO VERDE -TOMATE-HABAS | H1: VIERNES 27 DE FEBRERO OP1: CHULETA ASADA CON ARROZ Y PAPAS FRITAS OP2: MILANESA DE POLLO CON ARROZ Y PAPAS FRITAS | I1: TURNO ASIGNADO SEMANA 23 AL 27 DE FEBRERO 2026
A2: 1 | B2: 15163789-2 | C2: ABASCAL LIZANA CRISTOBAL MATIAS | D2: 2 | E2: 3 | F2: 1 | G2: 1 | H2: 1 | I2: AM
A3: =+A2+1 -> 2 | B3: 21161295-9 | C3: ACEVEDO CORTES NATALY JAVIERA | D3: 3 | E3: 3 | F3: 1 | G3: 2 | H3: 2 | I3: C
A4: =+A3+1 -> 3 | B4: 20054817-5 | C4: ACUÑA LAGOS JOSE IGNACIO | D4: 2 | E4: 3 | F4: 3 | G4: 3 | H4: 2 | I4: AM
A5: =+A4+1 -> 4 | B5: 20910090-8 | C5: ACUÑA PEÑA AXEL NICOLAS | D5: 3 | E5: 3 | F5: 3 | G5: 3 | H5: 2 | I5: PM
A6: =+A5+1 -> 5 | B6: 15995035-2 | C6: =VLOOKUP(B6,'[1]Base Trab'!$A$3:$B$243,2,0) -> ALARCON SANCHEZ ROSAMEL DEL TRANSITO | D6: 1 | E6: 1 | F6: 1 | G6: 1 | H6: 1 | I6: AM
A7: =+A6+1 -> 6 | B7: 21253994-5 | C7: ALBORNOZ ARAVENA GABRIEL MAXIMILIANO | D7: 2 | E7: 1 | F7: 1 | G7: 1 | H7: 1 | I7: AM
A8: =+A7+1 -> 7 | B8: 16780518-3 | C8: ALVAREZ CARRASCO FELIPE EDUARDO | D8: 2 | E8: 1 | F8: 1 | G8: 1 | H8: 2 | I8: PM
A9: =+A8+1 -> 8 | B9: 25045715-4 | C9: ARMAS RUIZ SEGUNDO DIONICIO | D9: 2 | E9: 3 | F9: 1 | G9: 3 | H9: 2 | I9: PM
A10: =+A9+1 -> 9 | B10: 11129943-9 | C10: AROS VARELA VICTOR HUGO | D10: 3 | E10: 1 | F10: 3 | G10: 3 | H10: 2 | I10: PM
A11: =+A10+1 -> 10 | B11: 25406099-2 | C11: =VLOOKUP(B11,'[1]Base Trab'!$A$3:$B$243,2,0) -> AVALOS CISNEROS FERNANDO | D11: 1 | E11: 1 | F11: 1 | G11: 1 | H11: 1 | I11: C
A12: =+A11+1 -> 11 | B12: 18925037-1 | C12: AVILA ARCE KEVIN EDUARDO | D12: 3 | E12: 3 | F12: 1 | G12: 3 | H12: 2 | I12: PM
A13: =+A12+1 -> 12 | B13: 25781650-8 | C13: AYENSA JIMENEZ DIANA VILLAR | D13: VACACIONES/ADMINISTRATIVO | E13: VACACIONES/ADMINISTRATIVO | F13: VACACIONES/ADMINISTRATIVO | G13: 2 | H13: 2 | I13: VAC
A14: =+A13+1 -> 13 | B14: 27474408-1 | C14: BELSUZARRE CAMPOS JUAN MARTÍN | D14: 2 | E14: 1 | F14: 1 | G14: 3 | H14: 1 | I14: PM
A15: =+A14+1 -> 14 | B15: 19681987-8 | C15: BRICEÑO SILVA KEVIN ALEJANDRO | D15: 2 | E15: 1 | F15: 3 | G15: 3 | H15: 2 | I15: C
A16: =+A15+1 -> 15 | B16: 22248240-2 | C16: BURGOS EUSTAQUIO ELMER | D16: 2 | E16: 3 | F16: 3 | G16: 3 | H16: 1 | I16: AM
A17: =+A16+1 -> 16 | B17: 20001354-9 | C17: CABEZA URREA MICHAEL BRANDON | D17: 2 | E17: 3 | F17: 1 | G17: 3 | H17: 1 | I17: PM
A18: =+A17+1 -> 17 | B18: 19754080-k | C18: CACERES CANALES LUIS ALFREDO | D18: 2 | E18: 3 | F18: 1 | G18: 1 | H18: 2 | I18: AM
A19: =+A18+1 -> 18 | B19: 20823745-4 | C19: CALDERON JORQUERA MICHAEL ESTEBAN | D19: 2 | E19: 3 | F19: 1 | G19: 1 | H19: 1 | I19: AM
A20: =+A19+1 -> 19 | B20: 27237007-9 | C20: CALLE ABRAMONTE GILBERTO | D20: 1 | E20: 3 | F20: 1 | G20: 3 | H20: 1 | I20: PM
A21: =+A20+1 -> 20 | B21: 17415201-2 | C21: CAMUS VERA ARIEL JESUS | D21: 2 | E21: 1 | F21: 1 | G21: 1 | H21: 1 | I21: PM
A22: =+A21+1 -> 21 | B22: 21475887-3 | C22: =VLOOKUP(B22,'[1]Base Trab'!$A$3:$B$243,2,0) -> CANO HERRERA JAVIER PERSI | D22: 1 | E22: 1 | F22: 1 | G22: 1 | H22: 1 | I22: PM
A23: =+A22+1 -> 22 | B23: 25371382-8 | C23: CAPCHA MEZA ALEX GERMAN | D23: 2 | E23: 3 | F23: 1 | G23: 2 | H23: 1 | I23: PM
A24: =+A23+1 -> 23 | B24: 22251178-k | C24: CARBAJAL CRUZADO VICTOR | D24: 2 | E24: 3 | F24: 1 | G24: 3 | H24: 1 | I24: PM
A25: =+A24+1 -> 24 | B25: 18726492-8 | C25: CARO VILLASECA DAVID ANTONIO | D25: 2 | E25: 3 | F25: 1 | G25: 1 | H25: 2 | I25: PM
A26: =+A25+1 -> 25 | B26: 22105181-5 | C26: CARQUIN GUAJARDO NICOLAS IGNACIO | D26: 2 | E26: 3 | F26: 1 | G26: 3 | H26: 2 | I26: AM
A27: =+A26+1 -> 26 | B27: 22105181-5 | C27: CARQUIN GUAJARDO NICOLAS IGNACIO | D27: 2 | E27: 3 | F27: 1 | G27: 3 | H27: 2 | I27: AM
A28: =+A27+1 -> 27 | B28: 9164465-7 | C28: CARRIZO GONZALEZ LEONEL ALAMIRO | D28: 2 | E28: 3 | F28: 1 | G28: 2 | H28: 1 | I28: AM
A29: =+A28+1 -> 28 | B29: 18385040-7 | C29: CASTILLO VERGARA CINDY MARLEN | D29: 2 | E29: 1 | F29: 2 | G29: 1 | H29: 1 | I29: AM
A30: =+A29+1 -> 29 | B30: 17150007-9 | C30: =VLOOKUP(B30,'[1]Base Trab'!$A$3:$B$243,2,0) -> COLIMAN RODRÍGUEZ FRANCISCO MANUEL | D30: 1 | E30: 1 | F30: 1 | G30: 1 | H30: 1 | I30: AM
A31: =+A30+1 -> 30 | B31: 27390589-8 | C31: CONDE CURI AGUSTIN | D31: 3 | E31: 3 | F31: 1 | G31: 3 | H31: 1 | I31: PM
A32: =+A31+1 -> 31 | B32: 19562442-9 | C32: CORTES CARMONA BASTIAN HERNAN | D32: 2 | E32: 3 | F32: 1 | G32: 2 | H32: 2 | I32: AM
A33: =+A32+1 -> 32 | B33: 19246868-K | C33: CRUZ C GONZALO | D33: 3 | E33: 3 | F33: 1 | G33: 2 | H33: 2 | I33: C
A34: =+A33+1 -> 33 | B34: 19187203-7 | C34: CRUZ GARCIA JORGE HERNAN | D34: 2 | E34: 2 | F34: 2 | G34: 2 | H34: 1 | I34: AM
A35: =+A34+1 -> 34 | B35: 25630389-2 | C35: DARIUS JHONNY | D35: 2 | E35: 3 | F35: 1 | G35: 2 | H35: 1 | I35: PM
A36: =+A35+1 -> 35 | B36: 14682203-7 | C36: DE LA CRUZ PIMINCHUMO VICTOR MANUEL | D36: VACACIONES/ADMINISTRATIVO | E36: VACACIONES/ADMINISTRATIVO | F36: VACACIONES/ADMINISTRATIVO | G36: VACACIONES/ADMINISTRATIVO | H36: VACACIONES/ADMINISTRATIVO | I36: VAC
A37: =+A36+1 -> 36 | B37: 20130821-6 | C37: =VLOOKUP(B37,'[1]Base Trab'!$A$3:$B$243,2,0) -> DELGADO LABRA NICOLAS IGNACIO | D37: 1 | E37: 1 | F37: 1 | G37: 1 | H37: 1 | I37: NOCHE
A38: =+A37+1 -> 37 | B38: 13800757-k | C38: DIAZ GARRIDO GUILLERMO ANTONIO | D38: 2 | E38: 1 | F38: 1 | G38: 3 | H38: 1 | I38: AM
A39: =+A38+1 -> 38 | B39: 13800757-k | C39: DIAZ GARRIDO GUILLERMO ANTONIO | D39: 2 | E39: 1 | F39: 1 | G39: 3 | H39: 1 | I39: AM
A40: =+A39+1 -> 39 | B40: 18127633-9 | C40: DURAN IRARRÁZABAL MIGUEL ANGEL | D40: 1 | E40: 3 | F40: 3 | G40: 3 | H40: 2 | I40: PM
...

Sheet TURNOS
A3: Cuenta de 23/02/2026 | C3: ID | G3: Cuenta de 24/02/2026 | I3: ID
A4: 23/02/2026 | B4: TURNO | C4: TURNO DIA | D4: TURNO TARDE | E4: Total general | G4: 24/02/2026 | H4: TURNO | I4: TURNO DIA | J4: TURNO TARDE | K4: Total general
A5: 1 | B5: AM | C5: 17 | E5: 17 | G5: 1 | H5: AM | I5: 26 | K5: 26
B6: C | C6: 11 | E6: 11 | H6: C | I6: 12 | K6: 12
B7: NOCHE | D7: 4 | E7: 4 | H7: NOCHE | J7: 4 | K7: 4
B8: PM | D8: 20 | E8: 20 | H8: PM | J8: 24 | K8: 24
A9: Total 1 | C9: 28 | D9: 24 | E9: 52 | G9: Total 1 | I9: 38 | J9: 28 | K9: 66
A10: 2 | B10: AM | C10: 36 | E10: 36 | G10: 2 | H10: AM | I10: 7 | K10: 7
B11: C | C11: 6 | E11: 6 | H11: C | I11: 2 | K11: 2
B12: NOCHE | D12: 2 | E12: 2 | H12: PM | J12: 3 | K12: 3
B13: PM | D13: 24 | E13: 24 | G13: Total 2 | I13: 9 | J13: 3 | K13: 12
A14: Total 2 | C14: 42 | D14: 26 | E14: 68 | G14: 3 | H14: AM | I14: 30 | K14: 30
A15: 3 | B15: AM | C15: 10 | E15: 10 | H15: C | I15: 14 | K15: 14
B16: C | C16: 10 | E16: 10 | H16: NOCHE | J16: 3 | K16: 3
B17: NOCHE | D17: 1 | E17: 1 | H17: PM | J17: 30 | K17: 30
B18: PM | D18: 12 | E18: 12 | G18: Total 3 | I18: 44 | J18: 33 | K18: 77
A19: Total 3 | C19: 20 | D19: 13 | E19: 33 | G19: Total general | I19: 91 | J19: 64 | K19: 155
A20: Total general | C20: 90 | D20: 63 | E20: 153
A23: Cuenta de 25/02/2026 | C23: ID
A24: 25/02/2026 | B24: TURNO | C24: TURNO DIA | D24: TURNO TARDE | E24: Total general | G24: Cuenta de 26/02/2026 | I24: ID
A25: 1 | B25: AM | C25: 40 | E25: 40 | G25: 26/02/2026 | H25: TURNO | I25: TURNO DIA | J25: TURNO TARDE | K25: Total general
B26: C | C26: 19 | E26: 19 | G26: 1 | H26: AM | I26: 28 | K26: 28
B27: NOCHE | D27: 5 | E27: 5 | H27: C | I27: 10 | K27: 10
B28: PM | D28: 43 | E28: 43 | H28: NOCHE | J28: 3 | K28: 3
A29: Total 1 | C29: 59 | D29: 48 | E29: 107 | H29: PM | J29: 27 | K29: 27
A30: 2 | B30: AM | C30: 5 | E30: 5 | G30: Total 1 | I30: 38 | J30: 30 | K30: 68
B31: C | C31: 1 | E31: 1 | G31: 2 | H31: AM | I31: 9 | K31: 9
B32: PM | D32: 3 | E32: 3 | H32: C | I32: 7 | K32: 7
A33: Total 2 | C33: 6 | D33: 3 | E33: 9 | H33: NOCHE | J33: 1 | K33: 1
A34: 3 | B34: AM | C34: 18 | E34: 18 | H34: PM | J34: 8 | K34: 8
B35: C | C35: 5 | E35: 5 | G35: Total 2 | I35: 16 | J35: 9 | K35: 25
B36: NOCHE | D36: 2 | E36: 2 | G36: 3 | H36: AM | I36: 26 | K36: 26
B37: PM | D37: 11 | E37: 11 | H37: C | I37: 10 | K37: 10
A38: Total 3 | C38: 23 | D38: 13 | E38: 36 | H38: NOCHE | J38: 3 | K38: 3
A39: Total general | C39: 88 | D39: 64 | E39: 152 | H39: PM | J39: 22 | K39: 22
G40: Total 3 | I40: 36 | J40: 25 | K40: 61
G41: Total general | I41: 90 | J41: 64 | K41: 154
A44: Cuenta de 27/02/2026 | C44: ID
A45: 27/02/2026 | B45: TURNO | C45: TURNO DIA | D45: TURNO TARDE | E45: Total general
A46: 1 | B46: AM | C46: 39 | E46: 39
...

Sheet BASE
A1: ID | B1: RUT | C1: Nombre completo | D1: 46076 | E1: 46077 | F1: 46078 | G1: 46079 | H1: 46080 | I1: TURNO
A2: TURNO DIA | B2: 15163789-2 | C2: ABASCAL LIZANA CRISTOBAL MATIAS | D2: 2 | E2: 3 | F2: 1 | G2: 1 | H2: 1 | I2: AM
A3: TURNO DIA | B3: 20054817-5 | C3: ACUÑA LAGOS JOSE IGNACIO | D3: 2 | E3: 3 | F3: 3 | G3: 3 | H3: 2 | I3: AM
A4: TURNO DIA | B4: 15995035-2 | C4: ALARCON SANCHEZ ROSAMEL DEL TRANSITO | D4: 1 | E4: 1 | F4: 1 | G4: 1 | H4: 1 | I4: AM
A5: TURNO DIA | B5: 21253994-5 | C5: ALBORNOZ ARAVENA GABRIEL MAXIMILIANO | D5: 2 | E5: 1 | F5: 1 | G5: 1 | H5: 1 | I5: AM
A6: TURNO DIA | B6: 22248240-2 | C6: BURGOS EUSTAQUIO ELMER | D6: 2 | E6: 3 | F6: 3 | G6: 3 | H6: 1 | I6: AM
A7: TURNO DIA | B7: 19754080-k | C7: CACERES CANALES LUIS ALFREDO | D7: 2 | E7: 3 | F7: 1 | G7: 1 | H7: 2 | I7: AM
A8: TURNO DIA | B8: 20823745-4 | C8: CALDERON JORQUERA MICHAEL ESTEBAN | D8: 2 | E8: 3 | F8: 1 | G8: 1 | H8: 1 | I8: AM
A9: TURNO DIA | B9: 22105181-5 | C9: CARQUIN GUAJARDO NICOLAS IGNACIO | D9: 2 | E9: 3 | F9: 1 | G9: 3 | H9: 2 | I9: AM
A10: TURNO DIA | B10: 22105181-5 | C10: CARQUIN GUAJARDO NICOLAS IGNACIO | D10: 2 | E10: 3 | F10: 1 | G10: 3 | H10: 2 | I10: AM
A11: TURNO DIA | B11: 9164465-7 | C11: CARRIZO GONZALEZ LEONEL ALAMIRO | D11: 2 | E11: 3 | F11: 1 | G11: 2 | H11: 1 | I11: AM
A12: TURNO DIA | B12: 18385040-7 | C12: CASTILLO VERGARA CINDY MARLEN | D12: 2 | E12: 1 | F12: 2 | G12: 1 | H12: 1 | I12: AM
... A19: TURNO DIA | B19: 10168667-1 | C19: ESCALONA FARIAS JUAN CARLOS | D19: 2 | E19: 1 | F19: 1 | G19: 3 | H19: 2 | I19: AM
A20: TURNO DIA | B20: 9487471-8 | C20: FLORES SAAVEDRA JOSE ALBERTO | D20: VACACIONES/ADMINISTRATIVO | E20: VACACIONES/ADMINISTRATIVO | F20: VACACIONES/ADMINISTRATIVO | G20: VACACIONES/ADMINISTRATIVO | H20: VACACIONES/ADMINISTRATIVO | I20: AM
A21: TURNO DIA | B21: 9481561-4 | C21: FLORES VIDAL FRANCISCO RODRIGO | D21: 3 | E21: 1 | F21: 3 | G21: 3 | H21: 1 | I21: AM
A22: TURNO DIA | B22: 15819718-9 | C22: GARCIA GARCIA NAYARET CATHERINNE | D22: 1 | E22: 3 | F22: 1 | G22: 1 | H22: 1 | I22: AM
A23: TURNO DIA | B23: 20099812-k | C23: GUZMAN MARTINEZ ANDRES FAVIAN | D23: 2 | E23: 3 | F23: 1 | G23: 1 | H23: 2 | I23: AM
A24: TURNO DIA | B24: 18603773-1 | C24: HERRERA ZAMBRANO CRISTOPHER IGNACIO | D24: 2 | E24: 3 | F24: 3 | G24: 1 | H24: 2 | I24: AM
A25: TURNO DIA | B25: 18603773-1 | C25: HERRERA ZAMBRANO CRISTOPHER IGNACIO | D25: 2 | E25: 3 | F25: 3 | G25: 1 | H25: 2 | I25: AM
A26: TURNO DIA | B26: 17110641-9 | C26: IRARRAZABAL VILLANUEVA ARIEL JESUS | D26: 1 | E26: 1 | F26: 1 | G26: 1 | H26: 1 | I26: AM
A27: TURNO DIA | B27: 19918837-2 | C27: LAGOS MARTINEZ FABIAN ALEJANDRO | D27: 2 | E27: 1 | F27: 3 | G27: 2 | H27: 2 | I27: AM
A28: TURNO DIA | B28: 19304186-8 | C28: LLANCAQUEO LLANCAQUEO SEBASTIAN ANTONIO | D28: 2 | E28: 3 | F28: 1 | G28: 3 | H28: 2 | I28: AM
A29: TURNO DIA | B29: 25664618-8 | C29: MENDEZ ANDRADE SANDI JOSE | D29: 2 | E29: 2 | F29: 1 | G29: 3 | H29: 1 | I29: AM
A30: TURNO DIA | B30: 25057090-2 | C30: MENDEZ LARA KRISTOPHER ALEXANDER | D30: 1 | E30: 1 | F30: 1 | G30: 1 | H30: 1 | I30: AM
A31: TURNO DIA | B31: 15234535-6 | C31: MENDEZ MANRIQUEZ GERARDO IVAN | D31: 2 | E31: 3 | F31: 3 | G31: 2 | H31: 1 | I31: AM
A32: TURNO DIA | B32: 27322835-7 | C32: MONJES PERAZA CHARLIS DANIEL | D32: 2 | E32: 2 | F32: 1 | G32: 1 | H32: 1 | I32: AM
... A46: TURNO DIA | B46: 18697014-4 | C46: REBOLLEDO TREJOS NICOLAS ALEJANDRO | D46: 1 | E46: 1 | F46: 1 | G46: 1 | H46: 1 | I46: AM
A47: TURNO DIA | B47: 17064952-4 | C47: REBOLLEDO VERA FABIÁN ESTEBAN | D47: VACACIONES/ADMINISTRATIVO | E47: VACACIONES/ADMINISTRATIVO | F47: VACACIONES/ADMINISTRATIVO | G47: VACACIONES/ADMINISTRATIVO | H47: VACACIONES/ADMINISTRATIVO | I47: AM
A48: TURNO DIA | B48: 18191670-2 | C48: RETAMAL SALAS EMANUEL EDUARDO | D48: 3 | E48: 3 | F48: 1 | G48: 3 | H48: 1 | I48: AM
A49: TURNO DIA | B49: 19886666-0 | C49: ROJAS BUCAREY ALEXANDER ADRIAN | D49: 2 | E49: 3 | F49: 3 | G49: 2 | H49: 2 | I49: AM
A50: TURNO DIA | B50: 21200182-1 | C50: RUIZ ORBEGOZO JORGE LUIS | D50: 2 | E50: 3 | F50: 1 | G50: 1 | H50: 2 | I50: AM
A51: TURNO DIA | B51: 15722772-6 | C51: SALAS BECERRA OSCAR ALBERTO | D51: 3 | E51: 1 | F51: 3 | G51: 3 | H51: 1 | I51: AM
A52: TURNO DIA | B52: 15539417-K | C52: SANDOVAL QUEZADA OSCAR FERNANDO | D52: 1 | E52: 1 | F52: 1 | G52: 1 | H52: 1 | I52: AM
A53: TURNO DIA | B53: 15168413-0 | C53: SANDOVAL RUBILAR FREDY ALEJANDRO | D53: 1 | E53: 1 | F53: 1 | G53: 1 | H53: 1 | I53: AM
A54: TURNO DIA | B54: 19162455-6 | C54: SEGUEL ALVAREZ JUAN CARLOS | D54: 2 | E54: 3 | F54: 1 | G54: 3 | H54: 2 | I54: AM
A55: TURNO DIA | B55: 18977190-8 | C55: SOTO GONZÁLEZ FRANCISCO ORLANDO | D55: 3 | E55: 3 | F55: 3 | G55: 3 | H55: 2 | I55: AM
A56: TURNO DIA | B56: 17738525-5 | C56: SOTO REUMANTE CHRISTIAN ALEXIS | D56: 1 | E56: 1 | F56: 1 | G56: 1 | H56: 1 | I56: AM
A57: TURNO DIA | B57: 26171464-7 | C57: TEJADA GRANADA CRISTIAN SOLANO | D57: 2 | E57: 2 | F57: 2 | G57: 1 | H57: 1 | I57: AM
A58: TURNO DIA | B58: 21739451-1 | C58: VALENZUELA CASTILLO SERGIO FELIPE | D58: 3 | E58: 3 | F58: 3 | G58: 3 | H58: 1 | I58: AM
A59: TURNO DIA | B59: 26682304-5 | C59: VEGA ESTRADA JUAN FELIX | D59: 2 | E59: 3 | F59: 2 | G59: 1 | H59: 1 | I59: AM
...

Sheet TOTEM
A1: ID | B1: RUT | C1: Nombre completo | D1: 46076 | E1: 46077 | F1: 46078 | G1: 46079 | H1: 46080 | I1: TURNO
D2: OP1: TOMATICAN CON ARROZ | E2: OP1: POROTOS PILCO CON CHORIZO | F2: OP1: CARNE MONGOLIANA CON ARROZ | G2: OP1: POLLO CUBOS ARVERJADO CON QUIFAROS | H2: OP1: CHULETA ASADA CON ARROZ Y PAPAS FRITAS
D3: OP2: POLLO AL JUGO CON ARROZ | E3: OP2: PRIETAS LIONESA CON PURE | F3: OP2: CHAMPIÑON SALTEADO CON ARROZ | G3: OP2: POLLO PESTO CON QUIFAROS | H3: OP2: MILANESA DE POLLO CON ARROZ Y PAPAS FRITAS
D4: OP3: HIPO TUTO CON REPOLLO-ZAPALLO ITALIANO-ZANAHORIA | E4: OP3: HIPO HAMBURGUESA DE VACUNO CON LECHUGA-TOMATE-CHOCLO | F4: OP3: HIPO FRITO DE ATUN CON LECHUGA-PAPAS COCIDAS-CEBOLLA EN PLUMAS | G4: OP3: HIPO BISTEC DE POLLO CON POROTO VERDE -TOMATE-HABAS
A6: TURNO DIA | B6: 15163789-2 | C6: ABASCAL LIZANA CRISTOBAL MATIAS | D6: 2 | E6: 3 | F6: 1 | G6: 1 | H6: 1 | I6: AM
A7: TURNO DIA | B7: 20054817-5 | C7: ACUÑA LAGOS JOSE IGNACIO | D7: 2 | E7: 3 | F7: 3 | G7: 3 | H7: 2 | I7: AM
A8: TURNO DIA | B8: 15995035-2 | C8: ALARCON SANCHEZ ROSAMEL DEL TRANSITO | D8: 1 | E8: 1 | F8: 1 | G8: 1 | H8: 1 | I8: AM
A9: TURNO DIA | B9: 21253994-5 | C9: ALBORNOZ ARAVENA GABRIEL MAXIMILIANO | D9: 2 | E9: 1 | F9: 1 | G9: 1 | H9: 1 | I9: AM
A10: TURNO DIA | B10: 22248240-2 | C10: BURGOS EUSTAQUIO ELMER | D10: 2 | E10: 3 | F10: 3 | G10: 3 | H10: 1 | I10: AM
A11: TURNO DIA | B11: 19754080-k | C11: CACERES CANALES LUIS ALFREDO | D11: 2 | E11: 3 | F11: 1 | G11: 1 | H11: 2 | I11: AM
A12: TURNO DIA | B12: 20823745-4 | C12: CALDERON JORQUERA MICHAEL ESTEBAN | D12: 2 | E12: 3 | F12: 1 | G12: 1 | H12: 1 | I12: AM
A13: TURNO DIA | B13: 22105181-5 | C13: CARQUIN GUAJARDO NICOLAS IGNACIO | D13: 2 | E13: 3 | F13: 1 | G13: 3 | H13: 2 | I13: AM
A14: TURNO DIA | B14: 22105181-5 | C14: CARQUIN GUAJARDO NICOLAS IGNACIO | D14: 2 | E14: 3 | F14: 1 | G14: 3 | H14: 2 | I14: AM
A15: TURNO DIA | B15: 9164465-7 | C15: CARRIZO GONZALEZ LEONEL ALAMIRO | D15: 2 | E15: 3 | F15: 1 | G15: 2 | H15: 1 | I15: AM
A16: TURNO DIA | B16: 18385040-7 | C16: CASTILLO VERGARA CINDY MARLEN | D16: 2 | E16: 1 | F16: 2 | G16: 1 | H16: 1 | I16: AM
A17: TURNO DIA | B17: 17150007-9 | C17: COLIMAN RODRÍGUEZ FRANCISCO MANUEL | D17: 1 | E17: 1 | F17: 1 | G17: 1 | H17: 1 | I17: AM
... A23: TURNO DIA | B23: 10168667-1 | C23: ESCALONA FARIAS JUAN CARLOS | D23: 2 | E23: 1 | F23: 1 | G23: 3 | H23: 2 | I23: AM
A24: TURNO DIA | B24: 9487471-8 | C24: FLORES SAAVEDRA JOSE ALBERTO | D24: VACACIONES/ADMINISTRATIVO | E24: VACACIONES/ADMINISTRATIVO | F24: VACACIONES/ADMINISTRATIVO | G24: VACACIONES/ADMINISTRATIVO | H24: VACACIONES/ADMINISTRATIVO | I24: AM
A25: TURNO DIA | B25: 9481561-4 | C25: FLORES VIDAL FRANCISCO RODRIGO | D25: 3 | E25: 1 | F25: 3 | G25: 3 | H25: 1 | I25: AM
A26: TURNO DIA | B26: 15819718-9 | C26: GARCIA GARCIA NAYARET CATHERINNE | D26: 1 | E26: 3 | F26: 1 | G26: 1 | H26: 1 | I26: AM
A27: TURNO DIA | B27: 20099812-k | C27: GUZMAN MARTINEZ ANDRES FAVIAN | D27: 2 | E27: 3 | F27: 1 | G27: 1 | H27: 2 | I27: AM
A28: TURNO DIA | B28: 18603773-1 | C28: HERRERA ZAMBRANO CRISTOPHER IGNACIO | D28: 2 | E28: 3 | F28: 3 | G28: 1 | H28: 2 | I28: AM
A29: TURNO DIA | B29: 18603773-1 | C29: HERRERA ZAMBRANO CRISTOPHER IGNACIO | D29: 2 | E29: 3 | F29: 3 | G29: 1 | H29: 2 | I29: AM
A30: TURNO DIA | B30: 17110641-9 | C30: IRARRAZABAL VILLANUEVA ARIEL JESUS | D30: 1 | E30: 1 | F30: 1 | G30: 1 | H30: 1 | I30: AM
A31: TURNO DIA | B31: 19918837-2 | C31: LAGOS MARTINEZ FABIAN ALEJANDRO | D31: 2 | E31: 1 | F31: 3 | G31: 2 | H31: 2 | I31: AM
A32: TURNO DIA | B32: 19304186-8 | C32: LLANCAQUEO LLANCAQUEO SEBASTIAN ANTONIO | D32: 2 | E32: 3 | F32: 1 | G32: 3 | H32: 2 | I32: AM
A33: TURNO DIA | B33: 25664618-8 | C33: MENDEZ ANDRADE SANDI JOSE | D33: 2 | E33: 2 | F33: 1 | G33: 3 | H33: 1 | I33: AM
A34: TURNO DIA | B34: 25057090-2 | C34: MENDEZ LARA KRISTOPHER ALEXANDER | D34: 1 | E34: 1 | F34: 1 | G34: 1 | H34: 1 | I34: AM
A35: TURNO DIA | B35: 15234535-6 | C35: MENDEZ MANRIQUEZ GERARDO IVAN | D35: 2 | E35: 3 | F35: 3 | G35: 2 | H35: 1 | I35: AM
A36: TURNO DIA | B36: 27322835-7 | C36: MONJES PERAZA CHARLIS DANIEL | D36: 2 | E36: 2 | F36: 1 | G36: 1 | H36: 1 | I36: AM
... A50: TURNO DIA | B50: 18697014-4 | C50: REBOLLEDO TREJOS NICOLAS ALEJANDRO | D50: 1 | E50: 1 | F50: 1 | G50: 1 | H50: 1 | I50: AM
A51: TURNO DIA | B51: 17064952-4 | C51: REBOLLEDO VERA FABIÁN ESTEBAN | D51: VACACIONES/ADMINISTRATIVO | E51: VACACIONES/ADMINISTRATIVO | F51: VACACIONES/ADMINISTRATIVO | G51: VACACIONES/ADMINISTRATIVO | H51: VACACIONES/ADMINISTRATIVO | I51: AM
A52: TURNO DIA | B52: 18191670-2 | C52: RETAMAL SALAS EMANUEL EDUARDO | D52: 3 | E52: 3 | F52: 1 | G52: 3 | H52: 1 | I52: AM
A53: TURNO DIA | B53: 19886666-0 | C53: ROJAS BUCAREY ALEXANDER ADRIAN | D53: 2 | E53: 3 | F53: 3 | G53: 2 | H53: 2 | I53: AM
A54: TURNO DIA | B54: 21200182-1 | C54: RUIZ ORBEGOZO JORGE LUIS | D54: 2 | E54: 3 | F54: 1 | G54: 1 | H54: 2 | I54: AM
A55: TURNO DIA | B55: 15722772-6 | C55: SALAS BECERRA OSCAR ALBERTO | D55: 3 | E55: 1 | F55: 3 | G55: 3 | H55: 1 | I55: AM
A56: TURNO DIA | B56: 15539417-K | C56: SANDOVAL QUEZADA OSCAR FERNANDO | D56: 1 | E56: 1 | F56: 1 | G56: 1 | H56: 1 | I56: AM
A57: TURNO DIA | B57: 15168413-0 | C57: SANDOVAL RUBILAR FREDY ALEJANDRO | D57: 1 | E57: 1 | F57: 1 | G57: 1 | H57: 1 | I57: AM
A58: TURNO DIA | B58: 19162455-6 | C58: SEGUEL ALVAREZ JUAN CARLOS | D58: 2 | E58: 3 | F58: 1 | G58: 3 | H58: 2 | I58: AM
A59: TURNO DIA | B59: 18977190-8 | C59: SOTO GONZÁLEZ FRANCISCO ORLANDO | D59: 3 | E59: 3 | F59: 3 | G59: 3 | H59: 2 | I59: AM
...

Sheet RESUMEN
C3: 46076 | D3: 46077 | E3: 46078 | F3: 46079 | G3: 46080
C5: OP1: TOMATICAN CON ARROZ | D5: OP1: POROTOS PILCO CON CHORIZO | E5: OP1: CARNE MONGOLIANA CON ARROZ | F5: OP1: POLLO CUBOS ARVERJADO CON QUIFAROS | G5: OP1: CHULETA ASADA CON ARROZ Y PAPAS FRITAS
C6: OP2: POLLO AL JUGO CON ARROZ | D6: OP2: PRIETAS LIONESA CON PURE | E6: OP2: CHAMPIÑON SALTEADO CON ARROZ | F6: OP2: POLLO PESTO CON QUIFAROS | G6: OP2: MILANESA DE POLLO CON ARROZ Y PAPAS FRITAS
C7: OP3: HIPO TUTO CON REPOLLO-ZAPALLO ITALIANO-ZANAHORIA | D7: OP3: HIPO HAMBURGUESA DE VACUNO CON LECHUGA-TOMATE-CHOCLO | E7: OP3: HIPO FRITO DE ATUN CON LECHUGA-PAPAS COCIDAS-CEBOLLA EN PLUMAS | F7: OP3: HIPO BISTEC DE POLLO CON POROTO VERDE -TOMATE-HABAS
B9: 1 | C9: =COUNTIF(BASE!D:D,RESUMEN!$B$9) -> 52 | D9: =COUNTIF(BASE!E:E,RESUMEN!$B$9) -> 66 | E9: =COUNTIF(BASE!F:F,RESUMEN!$B$9) -> 107 | F9: =COUNTIF(BASE!G:G,RESUMEN!$B$9) -> 68 | G9: =COUNTIF(BASE!H:H,RESUMEN!$B$9) -> 96
B10: 2 | C10: =COUNTIF(BASE!D:D,RESUMEN!$B$10) -> 68 | D10: =COUNTIF(BASE!E:E,RESUMEN!$B$10) -> 12 | E10: =COUNTIF(BASE!F:F,RESUMEN!$B$10) -> 9 | F10: =COUNTIF(BASE!G:G,RESUMEN!$B$10) -> 25 | G10: =COUNTIF(BASE!H:H,RESUMEN!$B$10) -> 59
B11: 3 | C11: =COUNTIF(BASE!D:D,RESUMEN!$B$11) -> 33 | D11: =COUNTIF(BASE!E:E,RESUMEN!$B$11) -> 77 | E11: =COUNTIF(BASE!F:F,RESUMEN!$B$11) -> 36 | F11: =COUNTIF(BASE!G:G,RESUMEN!$B$11) -> 61 | G11: =COUNTIF(BASE!H:H,RESUMEN!$B$11) -> 0
C13: =SUM(C9:C12) -> 153 | D13: =SUM(D9:D12) -> 155 | E13: =SUM(E9:E12) -> 152 | F13: =SUM(F9:F12) -> 154 | G13: =SUM(G9:G12) -> 155
C15: 153 | D15: 155 | E15: 152 | F15: 154 | G15: 155
C17: 153
C18: 155
C19: 152
C20: 154
C21: 155
